Workbook

Sheet 📊 Dashboard
B2: 📊 EARLY WARNING SIGNS — OPERATIONS DASHBOARD
B5: TEAM-LEVEL RISK SUMMARY
B6: Team | C6: Total Headcount | D6: 🟢 GREEN | E6: 🟡 YELLOW | F6: 🔴 RED | G6: ⚫ BLACK | H6: % At Risk (RED+BLACK) | I6: Avg Risk Score | J6: Top Indicator | K6: Action Priority
B7: Abigael Singcol Manalaysay | C7: 25 | D7: =COUNTIF('Abigael Singcol Manalaysay'!$G$5:$G$29,"*GREEN*") -> 0 | E7: =COUNTIF('Abigael Singcol Manalaysay'!$G$5:$G$29,"*YELLOW*") -> 25 | F7: =COUNTIF('Abigael Singcol Manalaysay'!$G$5:$G$29,"*RED*") -> 0 | G7: =COUNTIF('Abigael Singcol Manalaysay'!$G$5:$G$29,"*BLACK*") -> 0 | H7: =IFERROR((F7+G7)/C7,0) -> 0 | I7: =IFERROR(AVERAGE('Abigael Singcol Manalaysay'!$S$5:$S$29),0) -> 0 | K7: =IF(G7>0,"🚨 IMMEDIATE",IF(F7>0,"⚠️ HIGH",IF(E7>0,"📋 MONITOR","✅ STABLE"))) -> 📋 MONITOR
B8: Aida Marie Rodriguez | C8: 10 | D8: =COUNTIF('Aida Marie Rodriguez'!$G$5:$G$14,"*GREEN*") -> 0 | E8: =COUNTIF('Aida Marie Rodriguez'!$G$5:$G$14,"*YELLOW*") -> 10 | F8: =COUNTIF('Aida Marie Rodriguez'!$G$5:$G$14,"*RED*") -> 0 | G8: =COUNTIF('Aida Marie Rodriguez'!$G$5:$G$14,"*BLACK*") -> 0 | H8: =IFERROR((F8+G8)/C8,0) -> 0 | I8: =IFERROR(AVERAGE('Aida Marie Rodriguez'!$S$5:$S$14),0) -> 0 | K8: =IF(G8>0,"🚨 IMMEDIATE",IF(F8>0,"⚠️ HIGH",IF(E8>0,"📋 MONITOR","✅ STABLE"))) -> 📋 MONITOR
B9: Ailene Logronio Laure | C9: 18 | D9: =COUNTIF('Ailene Logronio Laure'!$G$5:$G$22,"*GREEN*") -> 0 | E9: =COUNTIF('Ailene Logronio Laure'!$G$5:$G$22,"*YELLOW*") -> 18 | F9: =COUNTIF('Ailene Logronio Laure'!$G$5:$G$22,"*RED*") -> 0 | G9: =COUNTIF('Ailene Logronio Laure'!$G$5:$G$22,"*BLACK*") -> 0 | H9: =IFERROR((F9+G9)/C9,0) -> 0 | I9: =IFERROR(AVERAGE('Ailene Logronio Laure'!$S$5:$S$22),0) -> 0 | K9: =IF(G9>0,"🚨 IMMEDIATE",IF(F9>0,"⚠️ HIGH",IF(E9>0,"📋 MONITOR","✅ STABLE"))) -> 📋 MONITOR
B10: Alanie Sanchez Lapuz | C10: 5 | D10: =COUNTIF('Alanie Sanchez Lapuz'!$G$5:$G$9,"*GREEN*") -> 0 | E10: =COUNTIF('Alanie Sanchez Lapuz'!$G$5:$G$9,"*YELLOW*") -> 5 | F10: =COUNTIF('Alanie Sanchez Lapuz'!$G$5:$G$9,"*RED*") -> 0 | G10: =COUNTIF('Alanie Sanchez Lapuz'!$G$5:$G$9,"*BLACK*") -> 0 | H10: =IFERROR((F10+G10)/C10,0) -> 0 | I10: =IFERROR(AVERAGE('Alanie Sanchez Lapuz'!$S$5:$S$9),0) -> 0 | K10: =IF(G10>0,"🚨 IMMEDIATE",IF(F10>0,"⚠️ HIGH",IF(E10>0,"📋 MONITOR","✅ STABLE"))) -> 📋 MONITOR
B11: Alyana Marie Jose Dela Cruz | C11: 24 | D11: =COUNTIF('Alyana Marie Jose Dela Cruz'!$G$5:$G$28,"*GREEN*") -> 0 | E11: =COUNTIF('Alyana Marie Jose Dela Cruz'!$G$5:$G$28,"*YELLOW*") -> 24 | F11: =COUNTIF('Alyana Marie Jose Dela Cruz'!$G$5:$G$28,"*RED*") -> 0 | G11: =COUNTIF('Alyana Marie Jose Dela Cruz'!$G$5:$G$28,"*BLACK*") -> 0 | H11: =IFERROR((F11+G11)/C11,0) -> 0 | I11: =IFERROR(AVERAGE('Alyana Marie Jose Dela Cruz'!$S$5:$S$28),0) -> 0 | K11: =IF(G11>0,"🚨 IMMEDIATE",IF(F11>0,"⚠️ HIGH",IF(E11>0,"📋 MONITOR","✅ STABLE"))) -> 📋 MONITOR
B12: Archiene Ross Calderon Herbias | C12: 18 | D12: =COUNTIF('Archiene Ross Calderon Herbias'!$G$5:$G$22,"*GREEN*") -> 0 | E12: =COUNTIF('Archiene Ross Calderon Herbias'!$G$5:$G$22,"*YELLOW*") -> 18 | F12: =COUNTIF('Archiene Ross Calderon Herbias'!$G$5:$G$22,"*RED*") -> 0 | G12: =COUNTIF('Archiene Ross Calderon Herbias'!$G$5:$G$22,"*BLACK*") -> 0 | H12: =IFERROR((F12+G12)/C12,0) -> 0 | I12: =IFERROR(AVERAGE('Archiene Ross Calderon Herbias'!$S$5:$S$22),0) -> 0 | K12: =IF(G12>0,"🚨 IMMEDIATE",IF(F12>0,"⚠️ HIGH",IF(E12>0,"📋 MONITOR","✅ STABLE"))) -> 📋 MONITOR
B13: Beulah Grace Arroyo Dacanay | E13: =COUNTIF('Beulah Grace Arroyo Dacanay'!$G$5:$G$23,"*YELLOW*") -> 19 | G13: =COUNTIF('Beulah Grace Arroyo Dacanay'!$G$5:$G$23,"*BLACK*") -> 0 | I13: =IFERROR(AVERAGE('Beulah Grace Arroyo Dacanay'!$S$5:$S$23),0) -> 0 | K13: =IF(G13>0,"🚨 IMMEDIATE",IF(F13>0,"⚠️ HIGH",IF(E13>0,"📋 MONITOR","✅ STABLE"))) -> 📋 MONITOR
B14: Carlo Angelo Lim Regalado | E14: =COUNTIF('Carlo Angelo Lim Regalado'!$G$5:$G$8,"*YELLOW*") -> 4 | G14: =COUNTIF('Carlo Angelo Lim Regalado'!$G$5:$G$8,"*BLACK*") -> 0 | I14: =IFERROR(AVERAGE('Carlo Angelo Lim Regalado'!$S$5:$S$8),0) -> 0 | K14: =IF(G14>0,"🚨 IMMEDIATE",IF(F14>0,"⚠️ HIGH",IF(E14>0,"📋 MONITOR","✅ STABLE"))) -> 📋 MONITOR
B15: Cathreen Aizha Ria Almazan | C15: 4 | D15: =COUNTIF('Cathreen Aizha Ria Almazan'!$G$5:$G$8,"*GREEN*") -> 0 | E15: =COUNTIF('Cathreen Aizha Ria Almazan'!$G$5:$G$8,"*YELLOW*") -> 4 | F15: =COUNTIF('Cathreen Aizha Ria Almazan'!$G$5:$G$8,"*RED*") -> 0 | G15: =COUNTIF('Cathreen Aizha Ria Almazan'!$G$5:$G$8,"*BLACK*") -> 0 | H15: =IFERROR((F15+G15)/C15,0) -> 0 | I15: =IFERROR(AVERAGE('Cathreen Aizha Ria Almazan'!$S$5:$S$8),0) -> 0 | K15: =IF(G15>0,"🚨 IMMEDIATE",IF(F15>0,"⚠️ HIGH",IF(E15>0,"📋 MONITOR","✅ STABLE"))) -> 📋 MONITOR
B16: Charlie Jr De Asis Cuartero
B17: Charmaine Garde Calupig | C17: 13 | D17: =COUNTIF('Charmaine Garde Calupig'!$G$5:$G$17,"*GREEN*") -> 0 | E17: =COUNTIF('Charmaine Garde Calupig'!$G$5:$G$17,"*YELLOW*") -> 13 | F17: =COUNTIF('Charmaine Garde Calupig'!$G$5:$G$17,"*RED*") -> 0 | G17: =COUNTIF('Charmaine Garde Calupig'!$G$5:$G$17,"*BLACK*") -> 0 | H17: =IFERROR((F17+G17)/C17,0) -> 0 | I17: =IFERROR(AVERAGE('Charmaine Garde Calupig'!$S$5:$S$17),0) -> 0 | K17: =IF(G17>0,"🚨 IMMEDIATE",IF(F17>0,"⚠️ HIGH",IF(E17>0,"📋 MONITOR","✅ STABLE"))) -> 📋 MONITOR
B18: Chrisel Lingat Martinez | C18: 10 | D18: =COUNTIF('Chrisel Lingat Martinez'!$G$5:$G$14,"*GREEN*") -> 0 | E18: =COUNTIF('Chrisel Lingat Martinez'!$G$5:$G$14,"*YELLOW*") -> 10 | F18: =COUNTIF('Chrisel Lingat Martinez'!$G$5:$G$14,"*RED*") -> 0 | G18: =COUNTIF('Chrisel Lingat Martinez'!$G$5:$G$14,"*BLACK*") -> 0 | H18: =IFERROR((F18+G18)/C18,0) -> 0 | I18: =IFERROR(AVERAGE('Chrisel Lingat Martinez'!$S$5:$S$14),0) -> 0 | K18: =IF(G18>0,"🚨 IMMEDIATE",IF(F18>0,"⚠️ HIGH",IF(E18>0,"📋 MONITOR","✅ STABLE"))) -> 📋 MONITOR
B19: Cres Marvin Alexander Alvaro
B20: Danica Villano Furiscal | C20: 19 | D20: =COUNTIF('Danica Villano Furiscal'!$G$5:$G$23,"*GREEN*") -> 0 | E20: =COUNTIF('Danica Villano Furiscal'!$G$5:$G$23,"*YELLOW*") -> 19 | F20: =COUNTIF('Danica Villano Furiscal'!$G$5:$G$23,"*RED*") -> 0 | G20: =COUNTIF('Danica Villano Furiscal'!$G$5:$G$23,"*BLACK*") -> 0 | H20: =IFERROR((F20+G20)/C20,0) -> 0 | I20: =IFERROR(AVERAGE('Danica Villano Furiscal'!$S$5:$S$23),0) -> 0 | K20: =IF(G20>0,"🚨 IMMEDIATE",IF(F20>0,"⚠️ HIGH",IF(E20>0,"📋 MONITOR","✅ STABLE"))) -> 📋 MONITOR
B21: Desiree Granpil Rudio | C21: 12 | D21: =COUNTIF('Desiree Granpil Rudio'!$G$5:$G$16,"*GREEN*") -> 0 | E21: =COUNTIF('Desiree Granpil Rudio'!$G$5:$G$16,"*YELLOW*") -> 12 | F21: =COUNTIF('Desiree Granpil Rudio'!$G$5:$G$16,"*RED*") -> 0 | G21: =COUNTIF('Desiree Granpil Rudio'!$G$5:$G$16,"*BLACK*") -> 0 | H21: =IFERROR((F21+G21)/C21,0) -> 0 | I21: =IFERROR(AVERAGE('Desiree Granpil Rudio'!$S$5:$S$16),0) -> 0 | K21: =IF(G21>0,"🚨 IMMEDIATE",IF(F21>0,"⚠️ HIGH",IF(E21>0,"📋 MONITOR","✅ STABLE"))) -> 📋 MONITOR
B22: Donabel Sabado Corrales | C22: 17 | D22: =COUNTIF('Donabel Sabado Corrales'!$G$5:$G$21,"*GREEN*") -> 0 | E22: =COUNTIF('Donabel Sabado Corrales'!$G$5:$G$21,"*YELLOW*") -> 17 | F22: =COUNTIF('Donabel Sabado Corrales'!$G$5:$G$21,"*RED*") -> 0 | G22: =COUNTIF('Donabel Sabado Corrales'!$G$5:$G$21,"*BLACK*") -> 0 | H22: =IFERROR((F22+G22)/C22,0) -> 0 | I22: =IFERROR(AVERAGE('Donabel Sabado Corrales'!$S$5:$S$21),0) -> 0 | K22: =IF(G22>0,"🚨 IMMEDIATE",IF(F22>0,"⚠️ HIGH",IF(E22>0,"📋 MONITOR","✅ STABLE"))) -> 📋 MONITOR
B23: Efren Jr Caitor Variacion | C23: 18 | D23: =COUNTIF('Efren Jr Caitor Variacion'!$G$5:$G$22,"*GREEN*") -> 0 | E23: =COUNTIF('Efren Jr Caitor Variacion'!$G$5:$G$22,"*YELLOW*") -> 18 | F23: =COUNTIF('Efren Jr Caitor Variacion'!$G$5:$G$22,"*RED*") -> 0 | G23: =COUNTIF('Efren Jr Caitor Variacion'!$G$5:$G$22,"*BLACK*") -> 0 | H23: =IFERROR((F23+G23)/C23,0) -> 0 | I23: =IFERROR(AVERAGE('Efren Jr Caitor Variacion'!$S$5:$S$22),0) -> 0 | K23: =IF(G23>0,"🚨 IMMEDIATE",IF(F23>0,"⚠️ HIGH",IF(E23>0,"📋 MONITOR","✅ STABLE"))) -> 📋 MONITOR
B24: Frederic Matthew Carlos Tuting | C24: 4 | D24: =COUNTIF('Frederic Matthew Carlos Tuting'!$G$5:$G$8,"*GREEN*") -> 0 | E24: =COUNTIF('Frederic Matthew Carlos Tuting'!$G$5:$G$8,"*YELLOW*") -> 4 | F24: =COUNTIF('Frederic Matthew Carlos Tuting'!$G$5:$G$8,"*RED*") -> 0 | G24: =COUNTIF('Frederic Matthew Carlos Tuting'!$G$5:$G$8,"*BLACK*") -> 0 | H24: =IFERROR((F24+G24)/C24,0) -> 0 | I24: =IFERROR(AVERAGE('Frederic Matthew Carlos Tuting'!$S$5:$S$8),0) -> 0 | K24: =IF(G24>0,"🚨 IMMEDIATE",IF(F24>0,"⚠️ HIGH",IF(E24>0,"📋 MONITOR","✅ STABLE"))) -> 📋 MONITOR
B25: Gay Olid Lobrin | C25: 16 | D25: =COUNTIF('Gay Olid Lobrin'!$G$5:$G$20,"*GREEN*") -> 0 | E25: =COUNTIF('Gay Olid Lobrin'!$G$5:$G$20,"*YELLOW*") -> 16 | F25: =COUNTIF('Gay Olid Lobrin'!$G$5:$G$20,"*RED*") -> 0 | G25: =COUNTIF('Gay Olid Lobrin'!$G$5:$G$20,"*BLACK*") -> 0 | H25: =IFERROR((F25+G25)/C25,0) -> 0 | I25: =IFERROR(AVERAGE('Gay Olid Lobrin'!$S$5:$S$20),0) -> 0 | K25: =IF(G25>0,"🚨 IMMEDIATE",IF(F25>0,"⚠️ HIGH",IF(E25>0,"📋 MONITOR","✅ STABLE"))) -> 📋 MONITOR
B26: Hector Ramiro Laboy- Lebron | C26: 14 | D26: =COUNTIF('Hector Ramiro Laboy- Lebron'!$G$5:$G$18,"*GREEN*") -> 0 | E26: =COUNTIF('Hector Ramiro Laboy- Lebron'!$G$5:$G$18,"*YELLOW*") -> 14 | F26: =COUNTIF('Hector Ramiro Laboy- Lebron'!$G$5:$G$18,"*RED*") -> 0 | G26: =COUNTIF('Hector Ramiro Laboy- Lebron'!$G$5:$G$18,"*BLACK*") -> 0 | H26: =IFERROR((F26+G26)/C26,0) -> 0 | I26: =IFERROR(AVERAGE('Hector Ramiro Laboy- Lebron'!$S$5:$S$18),0) -> 0 | K26: =IF(G26>0,"🚨 IMMEDIATE",IF(F26>0,"⚠️ HIGH",IF(E26>0,"📋 MONITOR","✅ STABLE"))) -> 📋 MONITOR
B27: Janice Carbonilla Rudila | C27: 6 | D27: =COUNTIF('Janice Carbonilla Rudila'!$G$5:$G$10,"*GREEN*") -> 0 | E27: =COUNTIF('Janice Carbonilla Rudila'!$G$5:$G$10,"*YELLOW*") -> 6 | F27: =COUNTIF('Janice Carbonilla Rudila'!$G$5:$G$10,"*RED*") -> 0 | G27: =COUNTIF('Janice Carbonilla Rudila'!$G$5:$G$10,"*BLACK*") -> 0 | H27: =IFERROR((F27+G27)/C27,0) -> 0 | I27: =IFERROR(AVERAGE('Janice Carbonilla Rudila'!$S$5:$S$10),0) -> 0 | K27: =IF(G27>0,"🚨 IMMEDIATE",IF(F27>0,"⚠️ HIGH",IF(E27>0,"📋 MONITOR","✅ STABLE"))) -> 📋 MONITOR
B28: Jean Paul Raymundo Larracas | C28: 22 | D28: =COUNTIF('Jean Paul Raymundo Larracas'!$G$5:$G$26,"*GREEN*") -> 0 | E28: =COUNTIF('Jean Paul Raymundo Larracas'!$G$5:$G$26,"*YELLOW*") -> 22 | F28: =COUNTIF('Jean Paul Raymundo Larracas'!$G$5:$G$26,"*RED*") -> 0 | G28: =COUNTIF('Jean Paul Raymundo Larracas'!$G$5:$G$26,"*BLACK*") -> 0 | H28: =IFERROR((F28+G28)/C28,0) -> 0 | I28: =IFERROR(AVERAGE('Jean Paul Raymundo Larracas'!$S$5:$S$26),0) -> 0 | K28: =IF(G28>0,"🚨 IMMEDIATE",IF(F28>0,"⚠️ HIGH",IF(E28>0,"📋 MONITOR","✅ STABLE"))) -> 📋 MONITOR
B29: Jennie Ann Mondido Abrasado | C29: 20 | D29: =COUNTIF('Jennie Ann Mondido Abrasado'!$G$5:$G$24,"*GREEN*") -> 0 | E29: =COUNTIF('Jennie Ann Mondido Abrasado'!$G$5:$G$24,"*YELLOW*") -> 20 | F29: =COUNTIF('Jennie Ann Mondido Abrasado'!$G$5:$G$24,"*RED*") -> 0 | G29: =COUNTIF('Jennie Ann Mondido Abrasado'!$G$5:$G$24,"*BLACK*") -> 0 | H29: =IFERROR((F29+G29)/C29,0) -> 0 | I29: =IFERROR(AVERAGE('Jennie Ann Mondido Abrasado'!$S$5:$S$24),0) -> 0 | K29: =IF(G29>0,"🚨 IMMEDIATE",IF(F29>0,"⚠️ HIGH",IF(E29>0,"📋 MONITOR","✅ STABLE"))) -> 📋 MONITOR
B30: Jennifer N BurgoS-Rivera | C30: 14 | D30: =COUNTIF('Jennifer N BurgoS-Rivera'!$G$5:$G$18,"*GREEN*") -> 0 | E30: =COUNTIF('Jennifer N BurgoS-Rivera'!$G$5:$G$18,"*YELLOW*") -> 14 | F30: =COUNTIF('Jennifer N BurgoS-Rivera'!$G$5:$G$18,"*RED*") -> 0 | G30: =COUNTIF('Jennifer N BurgoS-Rivera'!$G$5:$G$18,"*BLACK*") -> 0 | H30: =IFERROR((F30+G30)/C30,0) -> 0 | I30: =IFERROR(AVERAGE('Jennifer N BurgoS-Rivera'!$S$5:$S$18),0) -> 0 | K30: =IF(G30>0,"🚨 IMMEDIATE",IF(F30>0,"⚠️ HIGH",IF(E30>0,"📋 MONITOR","✅ STABLE"))) -> 📋 MONITOR
B31: Jeric Amazona Mansibang | C31: 18 | D31: =COUNTIF('Jeric Amazona Mansibang'!$G$5:$G$22,"*GREEN*") -> 0 | E31: =COUNTIF('Jeric Amazona Mansibang'!$G$5:$G$22,"*YELLOW*") -> 18 | F31: =COUNTIF('Jeric Amazona Mansibang'!$G$5:$G$22,"*RED*") -> 0 | G31: =COUNTIF('Jeric Amazona Mansibang'!$G$5:$G$22,"*BLACK*") -> 0 | H31: =IFERROR((F31+G31)/C31,0) -> 0 | I31: =IFERROR(AVERAGE('Jeric Amazona Mansibang'!$S$5:$S$22),0) -> 0 | K31: =IF(G31>0,"🚨 IMMEDIATE",IF(F31>0,"⚠️ HIGH",IF(E31>0,"📋 MONITOR","✅ STABLE"))) -> 📋 MONITOR
B32: John Earl Melitado Lagare | C32: 16 | D32: =COUNTIF('John Earl Melitado Lagare'!$G$5:$G$20,"*GREEN*") -> 0 | E32: =COUNTIF('John Earl Melitado Lagare'!$G$5:$G$20,"*YELLOW*") -> 16 | F32: =COUNTIF('John Earl Melitado Lagare'!$G$5:$G$20,"*RED*") -> 0 | G32: =COUNTIF('John Earl Melitado Lagare'!$G$5:$G$20,"*BLACK*") -> 0 | H32: =IFERROR((F32+G32)/C32,0) -> 0 | I32: =IFERROR(AVERAGE('John Earl Melitado Lagare'!$S$5:$S$20),0) -> 0 | K32: =IF(G32>0,"🚨 IMMEDIATE",IF(F32>0,"⚠️ HIGH",IF(E32>0,"📋 MONITOR","✅ STABLE"))) -> 📋 MONITOR
B33: Johnny Rey Diaz Bonocan
B34: Joseph Andrew Cera Ballesteros | C34: 15 | D34: =COUNTIF('Joseph Andrew Cera Ballesteros'!$G$5:$G$19,"*GREEN*") -> 0 | E34: =COUNTIF('Joseph Andrew Cera Ballesteros'!$G$5:$G$19,"*YELLOW*") -> 15 | F34: =COUNTIF('Joseph Andrew Cera Ballesteros'!$G$5:$G$19,"*RED*") -> 0 | G34: =COUNTIF('Joseph Andrew Cera Ballesteros'!$G$5:$G$19,"*BLACK*") -> 0 | H34: =IFERROR((F34+G34)/C34,0) -> 0 | I34: =IFERROR(AVERAGE('Joseph Andrew Cera Ballesteros'!$S$5:$S$19),0) -> 0 | K34: =IF(G34>0,"🚨 IMMEDIATE",IF(F34>0,"⚠️ HIGH",IF(E34>0,"📋 MONITOR","✅ STABLE"))) -> 📋 MONITOR
B35: Kathrina Mae Suycano Silangan | C35: 21 | D35: =COUNTIF('Kathrina Mae Suycano Silangan'!$G$5:$G$25,"*GREEN*") -> 0 | E35: =COUNTIF('Kathrina Mae Suycano Silangan'!$G$5:$G$25,"*YELLOW*") -> 21 | F35: =COUNTIF('Kathrina Mae Suycano Silangan'!$G$5:$G$25,"*RED*") -> 0 | G35: =COUNTIF('Kathrina Mae Suycano Silangan'!$G$5:$G$25,"*BLACK*") -> 0 | H35: =IFERROR((F35+G35)/C35,0) -> 0 | I35: =IFERROR(AVERAGE('Kathrina Mae Suycano Silangan'!$S$5:$S$25),0) -> 0 | K35: =IF(G35>0,"🚨 IMMEDIATE",IF(F35>0,"⚠️ HIGH",IF(E35>0,"📋 MONITOR","✅ STABLE"))) -> 📋 MONITOR
B36: Khyno Elimanco Cortez | C36: 19 | D36: =COUNTIF('Khyno Elimanco Cortez'!$G$5:$G$23,"*GREEN*") -> 0 | E36: =COUNTIF('Khyno Elimanco Cortez'!$G$5:$G$23,"*YELLOW*") -> 19 | F36: =COUNTIF('Khyno Elimanco Cortez'!$G$5:$G$23,"*RED*") -> 0 | G36: =COUNTIF('Khyno Elimanco Cortez'!$G$5:$G$23,"*BLACK*") -> 0 | H36: =IFERROR((F36+G36)/C36,0) -> 0 | I36: =IFERROR(AVERAGE('Khyno Elimanco Cortez'!$S$5:$S$23),0) -> 0 | K36: =IF(G36>0,"🚨 IMMEDIATE",IF(F36>0,"⚠️ HIGH",IF(E36>0,"📋 MONITOR","✅ STABLE"))) -> 📋 MONITOR
B37: Kristel Angelica Valerio | C37: 11 | D37: =COUNTIF('Kristel Angelica Valerio'!$G$5:$G$15,"*GREEN*") -> 0 | E37: =COUNTIF('Kristel Angelica Valerio'!$G$5:$G$15,"*YELLOW*") -> 11 | F37: =COUNTIF('Kristel Angelica Valerio'!$G$5:$G$15,"*RED*") -> 0 | G37: =COUNTIF('Kristel Angelica Valerio'!$G$5:$G$15,"*BLACK*") -> 0 | H37: =IFERROR((F37+G37)/C37,0) -> 0 | I37: =IFERROR(AVERAGE('Kristel Angelica Valerio'!$S$5:$S$15),0) -> 0 | K37: =IF(G37>0,"🚨 IMMEDIATE",IF(F37>0,"⚠️ HIGH",IF(E37>0,"📋 MONITOR","✅ STABLE"))) -> 📋 MONITOR
B38: Lea Ibag Fernandez | C38: 20 | D38: =COUNTIF('Lea Ibag Fernandez'!$G$5:$G$24,"*GREEN*") -> 0 | E38: =COUNTIF('Lea Ibag Fernandez'!$G$5:$G$24,"*YELLOW*") -> 20 | F38: =COUNTIF('Lea Ibag Fernandez'!$G$5:$G$24,"*RED*") -> 0 | G38: =COUNTIF('Lea Ibag Fernandez'!$G$5:$G$24,"*BLACK*") -> 0 | H38: =IFERROR((F38+G38)/C38,0) -> 0 | I38: =IFERROR(AVERAGE('Lea Ibag Fernandez'!$S$5:$S$24),0) -> 0 | K38: =IF(G38>0,"🚨 IMMEDIATE",IF(F38>0,"⚠️ HIGH",IF(E38>0,"📋 MONITOR","✅ STABLE"))) -> 📋 MONITOR
B39: Leah Bernadette Lavalle Bringas | C39: 16 | D39: =COUNTIF('Leah Bernadette Lavalle Bringas'!$G$5:$G$20,"*GREEN*") -> 0 | E39: =COUNTIF('Leah Bernadette Lavalle Bringas'!$G$5:$G$20,"*YELLOW*") -> 16 | F39: =COUNTIF('Leah Bernadette Lavalle Bringas'!$G$5:$G$20,"*RED*") -> 0 | G39: =COUNTIF('Leah Bernadette Lavalle Bringas'!$G$5:$G$20,"*BLACK*") -> 0 | H39: =IFERROR((F39+G39)/C39,0) -> 0 | I39: =IFERROR(AVERAGE('Leah Bernadette Lavalle Bringas'!$S$5:$S$20),0) -> 0 | K39: =IF(G39>0,"🚨 IMMEDIATE",IF(F39>0,"⚠️ HIGH",IF(E39>0,"📋 MONITOR","✅ STABLE"))) -> 📋 MONITOR
B40: Lee Stephen Valde Fat | C40: 2 | D40: =COUNTIF('Lee Stephen Valde Fat'!$G$5:$G$6,"*GREEN*") -> 0 | E40: =COUNTIF('Lee Stephen Valde Fat'!$G$5:$G$6,"*YELLOW*") -> 2 | F40: =COUNTIF('Lee Stephen Valde Fat'!$G$5:$G$6,"*RED*") -> 0 | G40: =COUNTIF('Lee Stephen Valde Fat'!$G$5:$G$6,"*BLACK*") -> 0 | H40: =IFERROR((F40+G40)/C40,0) -> 0 | I40: =IFERROR(AVERAGE('Lee Stephen Valde Fat'!$S$5:$S$6),0) -> 0 | K40: =IF(G40>0,"🚨 IMMEDIATE",IF(F40>0,"⚠️ HIGH",IF(E40>0,"📋 MONITOR","✅ STABLE"))) -> 📋 MONITOR
B41: Leou Alven Narito Comendador | C41: 3 | D41: =COUNTIF('Leou Alven Narito Comendador'!$G$5:$G$7,"*GREEN*") -> 0 | E41: =COUNTIF('Leou Alven Narito Comendador'!$G$5:$G$7,"*YELLOW*") -> 3 | F41: =COUNTIF('Leou Alven Narito Comendador'!$G$5:$G$7,"*RED*") -> 0 | G41: =COUNTIF('Leou Alven Narito Comendador'!$G$5:$G$7,"*BLACK*") -> 0 | H41: =IFERROR((F41+G41)/C41,0) -> 0 | I41: =IFERROR(AVERAGE('Leou Alven Narito Comendador'!$S$5:$S$7),0) -> 0 | K41: =IF(G41>0,"🚨 IMMEDIATE",IF(F41>0,"⚠️ HIGH",IF(E41>0,"📋 MONITOR","✅ STABLE"))) -> 📋 MONITOR
B42: Lovely Mae Enot Sacurom | C42: 19 | D42: =COUNTIF('Lovely Mae Enot Sacurom'!$G$5:$G$23,"*GREEN*") -> 0 | E42: =COUNTIF('Lovely Mae Enot Sacurom'!$G$5:$G$23,"*YELLOW*") -> 19 | F42: =COUNTIF('Lovely Mae Enot Sacurom'!$G$5:$G$23,"*RED*") -> 0 | G42: =COUNTIF('Lovely Mae Enot Sacurom'!$G$5:$G$23,"*BLACK*") -> 0 | H42: =IFERROR((F42+G42)/C42,0) -> 0 | I42: =IFERROR(AVERAGE('Lovely Mae Enot Sacurom'!$S$5:$S$23),0) -> 0 | K42: =IF(G42>0,"🚨 IMMEDIATE",IF(F42>0,"⚠️ HIGH",IF(E42>0,"📋 MONITOR","✅ STABLE"))) -> 📋 MONITOR
B43: Luis Joel Traverso Rodriguez | C43: 4 | D43: =COUNTIF('Luis Joel Traverso Rodriguez'!$G$5:$G$8,"*GREEN*") -> 0 | E43: =COUNTIF('Luis Joel Traverso Rodriguez'!$G$5:$G$8,"*YELLOW*") -> 4 | F43: =COUNTIF('Luis Joel Traverso Rodriguez'!$G$5:$G$8,"*RED*") -> 0 | G43: =COUNTIF('Luis Joel Traverso Rodriguez'!$G$5:$G$8,"*BLACK*") -> 0 | H43: =IFERROR((F43+G43)/C43,0) -> 0 | I43: =IFERROR(AVERAGE('Luis Joel Traverso Rodriguez'!$S$5:$S$8),0) -> 0 | K43: =IF(G43>0,"🚨 IMMEDIATE",IF(F43>0,"⚠️ HIGH",IF(E43>0,"📋 MONITOR","✅ STABLE"))) -> 📋 MONITOR
...

Sheet Team Leou
B2: 🔍 EARLY WARNING SIGNS TRACKER — TEAM LEOU
B4: # | C4: Employee Name | D4: Position | E4: Date Hired | F4: Risk Status | G4: Frequent Tardiness | H4: Increased Absences | I4: Low Productivity | J4: Disengagement in Team Huddles | K4: Job Hunting Signals | L4: Conflicts with Teammates | M4: Decline in QA/NPS Scores | N4: Reduced Initiative | O4: Requesting LOA/Personal Leaves | P4: Withdrawal from Social Activities | Q4: With Active CAP? | R4: Risk Score | S4: Rating for the past 3 months | T4: TL Notes | U4: Last Updated
B5: 1 | C5: Xena Garcia | D5: QA Analyst | E5: 03/01/2020 | F5: ⚫ BLACK | G5: YES | H5: YES | I5: YES | J5: YES | K5: YES | L5: NO | M5: NO | N5: YES | O5: NO | P5: NO | Q5: YES | R5: =COUNTIF(G5:Q5,"YES") -> 7
B6: 2 | C6: Jose Concepcion | D6: Subject Matter Expert | E6: 09/01/2022 | F6: 🔴 RED | G6: NO | H6: YES | I6: YES | J6: NO | K6: NO | L6: NO | M6: YES | N6: NO | O6: NO | P6: YES | Q6: YES | R6: =COUNTIF(G6:Q6,"YES") -> 5
B7: 3 | C7: Ivy Dela Cruz | D7: Trainer | E7: 12/01/2019 | F7: 🔴 RED | G7: NO | H7: YES | I7: NO | J7: YES | K7: NO | L7: NO | M7: NO | N7: YES | O7: YES | P7: NO | Q7: YES | R7: =COUNTIF(G7:Q7,"YES") -> 5
B8: 4 | C8: Trisha Ramos | D8: Senior Specialist | E8: 09/01/2023 | F8: 🟢 GREEN | G8: NO | H8: NO | I8: NO | J8: YES | K8: YES | L8: NO | M8: NO | N8: YES | O8: YES | P8: YES | Q8: YES | R8: =COUNTIF(G8:Q8,"YES") -> 6
B9: 5 | C9: Ems Garcia | D9: Subject Matter Expert | E9: 02/01/2019 | F9: ⚫ BLACK | G9: YES | H9: NO | I9: YES | J9: YES | K9: NO | L9: NO | M9: YES | N9: NO | O9: NO | P9: NO | Q9: YES | R9: =COUNTIF(G9:Q9,"YES") -> 5
B10: 6 | C10: Alma Concepcion | D10: Trainer | E10: 09/01/2020 | F10: 🟡 YELLOW | G10: NO | H10: NO | I10: NO | J10: NO | K10: NO | L10: NO | M10: YES | N10: YES | O10: YES | P10: YES | Q10: YES | R10: =COUNTIF(G10:Q10,"YES") -> 5
B11: 7 | C11: Ric Cruz | D11: QA Analyst | E11: 10/01/2019 | F11: ⚫ BLACK | G11: NO | H11: YES | I11: YES | J11: YES | K11: YES | L11: YES | M11: YES | N11: YES | O11: NO | P11: YES | Q11: YES | R11: =COUNTIF(G11:Q11,"YES") -> 9
B12: 8 | C12: Uma Mendoza | D12: Subject Matter Expert | E12: 05/01/2020 | F12: ⚫ BLACK | G12: YES | H12: NO | I12: YES | J12: NO | K12: NO | L12: NO | M12: YES | N12: NO | O12: NO | P12: YES | Q12: YES | R12: =COUNTIF(G12:Q12,"YES") -> 5
B13: 9 | C13: Ana Santos | D13: PA Specialist | E13: 11/01/2019 | F13: ⚫ BLACK | G13: NO | H13: NO | I13: NO | J13: NO | K13: YES | L13: YES | M13: YES | N13: NO | O13: NO | P13: YES | Q13: YES | R13: =COUNTIF(G13:Q13,"YES") -> 5
B14: 10 | C14: Carlo Flores | D14: Senior Specialist | E14: 04/01/2020 | F14: ⚫ BLACK | G14: YES | H14: NO | I14: YES | J14: NO | K14: NO | L14: YES | M14: YES | N14: NO | O14: NO | P14: YES | Q14: YES | R14: =COUNTIF(G14:Q14,"YES") -> 6
B15: 11 | C15: Trisha Rivera | D15: PA Specialist | E15: 01/01/2023 | F15: 🟢 GREEN | G15: YES | H15: YES | I15: NO | J15: NO | K15: NO | L15: YES | M15: NO | N15: YES | O15: YES | P15: NO | Q15: YES | R15: =COUNTIF(G15:Q15,"YES") -> 6
B16: 12 | C16: Val Santos | D16: PA Specialist | E16: 05/01/2022 | F16: ⚫ BLACK | G16: NO | H16: NO | I16: NO | J16: NO | K16: YES | L16: YES | M16: NO | N16: YES | O16: YES | P16: NO | Q16: YES | R16: =COUNTIF(G16:Q16,"YES") -> 5
... B23: 19 | C23: Maria Peralta | D23: PA Specialist | E23: 05/01/2022 | F23: 🟢 GREEN | G23: YES | H23: NO | I23: YES | J23: NO | K23: YES | L23: NO | M23: NO | N23: NO | O23: NO | P23: YES | Q23: YES | R23: =COUNTIF(G23:Q23,"YES") -> 5

Sheet ⚫ Confirmed Attrition
B2: ⚫ CONFIRMED ATTRITION REGISTER — All Teams
B4: # | C4: Employee Name | D4: Team | E4: Position | F4: Date Hired | G4: Confirmed Date | H4: Last Risk Status | I4: TL Notes
B5: 1 | C5: Xena Garcia | D5: Team Leou | E5: PA Specialist | F5: 44256 | G5: 45757 | H5: ⚫ BLACK | I5: Resignation confirmed.
B6: 2 | C6: Jose Concepcion | D6: Team Leou | E6: Senior Specialist | F6: 44256 | G6: 45757 | H6: ⚫ BLACK | I6: Resignation confirmed.
B7: 3 | C7: Donna Soriano | D7: Team Alpha | E7: Senior Specialist | F7: 44256 | G7: 45757 | H7: ⚫ BLACK | I7: Resignation confirmed.
B8: 4 | C8: Jake Bautista | D8: Team Alpha | E8: Senior Specialist | F8: 44256 | G8: 45757 | H8: ⚫ BLACK | I8: Resignation confirmed.
B9: 5 | C9: Gem Aquino | D9: Team Beta | E9: Senior Specialist | F9: 44256 | G9: 45757 | H9: ⚫ BLACK | I9: Resignation confirmed.
B10: 6 | C10: Carlo Dizon | D10: Team Beta | E10: PA Specialist | F10: 44256 | G10: 45757 | H10: ⚫ BLACK | I10: Resignation confirmed.
B11: 7 | C11: Alma Bautista | D11: Team Gamma | E11: Senior Specialist | F11: 44256 | G11: 45757 | H11: ⚫ BLACK | I11: Resignation confirmed.
B12: 8 | C12: Gem Peralta | D12: Team Gamma | E12: PA Specialist | F12: 44256 | G12: 45757 | H12: ⚫ BLACK | I12: Resignation confirmed.
B14: 📌 HOW TO USE: Go to any Team sheet → change Risk Status to '⚫ BLACK' → manually copy that row here OR use the Macro button on the Dashboard to auto-transfer.

Sheet 📋 Legend & Guide
B2: 📋 LEGEND & USER GUIDE
B4: STATUS | C4: MEANING | D4: ACTION REQUIRED
B5: 🟢 GREEN | C5: Employee is engaged and performing well. | D5: Continue regular check-ins and recognition.
B6: 🟡 YELLOW | C6: Mild warning signs present (1–3 indicators). | D6: Schedule 1-on-1 coaching. Document observations.
B7: 🔴 RED | C7: Multiple warning signs (4–7 indicators). High flight risk. | D7: Immediate retention conversation. Escalate to HR if needed.
B8: ⚫ BLACK | C8: Confirmed resignation or termination. | D8: Transfer to Confirmed Attrition sheet. Begin transition plan.
B11: WARNING INDICATORS EXPLAINED
B12: Frequent Tardiness | C12: Arriving late consistently (3+ times/week).
B13: Increased Absences | C13: Unplanned or unexcused absences rising.
B14: Low Productivity | C14: Consistent miss of daily/weekly targets.
B15: Disengagement in Team Huddles | C15: Not participating, camera-off, unresponsive.
B16: Job Hunting Signals | C16: LinkedIn activity, interviews, vague schedule blocks.
B17: Conflicts with Teammates | C17: Tension, complaints, or friction with peers.
B18: Decline in QA Scores | C18: QA average dropping below 98%.
B19: Reduced Initiative | C19: No longer taking on extra tasks or projects.
B20: Requesting LOA/Personal Leaves | C20: Increase in leave requests or personal time.
B21: Withdrawal from Social Activities | C21: No longer joining team events or celebrations.

Sheet Abigael Singcol Manalaysay
B2: 🔍 EARLY WARNING SIGNS TRACKER — ABIGAEL SINGCOL MANALAYSAY
B4: # | C4: Employee Name | D4: Employee ID | E4: Position | F4: Date Hired | G4: Risk Status | H4: Frequent Tardiness | I4: Increased Absences | J4: Low Productivity | K4: Disengagement in Team Huddles | L4: Job Hunting Signals | M4: Conflicts with Teammates | N4: Decline in QA/NPS Scores | O4: Reduced Initiative | P4: Requesting LOA/Leaves | Q4: Withdrawal from Social Activities | R4: With Active CAP? | S4: Risk Score | T4: Rating (Last 3 Mo.) | U4: TL Notes | V4: Last Updated
B5: 1 | C5: Cuaresma,Sherap Don De Guzman | D5: 1370513 | G5: 🟡 YELLOW | H5: NO | I5: NO | J5: NO | K5: NO | L5: NO | M5: NO | N5: NO | O5: NO | P5: NO | Q5: NO | R5: NO | S5: =COUNTIF(H5:R5,"YES") -> 0
B6: 2 | C6: Mustacisa,Jella Mae Pepito | D6: 1616547 | G6: 🟡 YELLOW | H6: NO | I6: NO | J6: NO | K6: NO | L6: NO | M6: NO | N6: NO | O6: NO | P6: NO | Q6: NO | R6: NO | S6: =COUNTIF(H6:R6,"YES") -> 0
B7: 3 | C7: Villaver,Ma Alphecca Win | D7: 1748534 | G7: 🟡 YELLOW | H7: NO | I7: NO | J7: NO | K7: NO | L7: NO | M7: NO | N7: NO | O7: NO | P7: NO | Q7: NO | R7: NO | S7: =COUNTIF(H7:R7,"YES") -> 0
B8: 4 | C8: Delos Santos,Nikki Jane Naraja | D8: 1772477 | G8: 🟡 YELLOW | H8: NO | I8: NO | J8: NO | K8: NO | L8: NO | M8: NO | N8: NO | O8: NO | P8: NO | Q8: NO | R8: NO | S8: =COUNTIF(H8:R8,"YES") -> 0
B9: 5 | C9: San Diego,Charisse Mayo | D9: 2116345 | G9: 🟡 YELLOW | H9: NO | I9: NO | J9: NO | K9: NO | L9: NO | M9: NO | N9: NO | O9: NO | P9: NO | Q9: NO | R9: NO | S9: =COUNTIF(H9:R9,"YES") -> 0
B10: 6 | C10: Belen,Carmella Silva | D10: 2116392 | G10: 🟡 YELLOW | H10: NO | I10: NO | J10: NO | K10: NO | L10: NO | M10: NO | N10: NO | O10: NO | P10: NO | Q10: NO | R10: NO | S10: =COUNTIF(H10:R10,"YES") -> 0
B11: 7 | C11: Santos,Jennilyn Chan | D11: 2122476 | G11: 🟡 YELLOW | H11: NO | I11: NO | J11: NO | K11: NO | L11: NO | M11: NO | N11: NO | O11: NO | P11: NO | Q11: NO | R11: NO | S11: =COUNTIF(H11:R11,"YES") -> 0
B12: 8 | C12: Rondina,Angelica Gabieta | D12: 2133444 | G12: 🟡 YELLOW | H12: NO | I12: NO | J12: NO | K12: NO | L12: NO | M12: NO | N12: NO | O12: NO | P12: NO | Q12: NO | R12: NO | S12: =COUNTIF(H12:R12,"YES") -> 0
B13: 9 | C13: Mengote,Mariven Ocfemia | D13: 2133445 | G13: 🟡 YELLOW | H13: NO | I13: NO | J13: NO | K13: NO | L13: NO | M13: NO | N13: NO | O13: NO | P13: NO | Q13: NO | R13: NO | S13: =COUNTIF(H13:R13,"YES") -> 0
B14: 10 | C14: Napay,Rowena Joice Baguios | D14: 2133455 | G14: 🟡 YELLOW | H14: NO | I14: NO | J14: NO | K14: NO | L14: NO | M14: NO | N14: NO | O14: NO | P14: NO | Q14: NO | R14: NO | S14: =COUNTIF(H14:R14,"YES") -> 0
B15: 11 | C15: Pamplona,Princess Joanna Yamson | D15: 2243267 | G15: 🟡 YELLOW | H15: NO | I15: NO | J15: NO | K15: NO | L15: NO | M15: NO | N15: NO | O15: NO | P15: NO | Q15: NO | R15: NO | S15: =COUNTIF(H15:R15,"YES") -> 0
B16: 12 | C16: Mollasco,Princess Camille Brazil | D16: 2244157 | G16: 🟡 YELLOW | H16: NO | I16: NO | J16: NO | K16: NO | L16: NO | M16: NO | N16: NO | O16: NO | P16: NO | Q16: NO | R16: NO | S16: =COUNTIF(H16:R16,"YES") -> 0
... B29: 25 | C29: Laory,Ramil John | D29: 900121715 | G29: 🟡 YELLOW | H29: NO | I29: NO | J29: NO | K29: NO | L29: NO | M29: NO | N29: NO | O29: NO | P29: NO | Q29: NO | R29: NO | S29: =COUNTIF(H29:R29,"YES") -> 0

Sheet Aida Marie Rodriguez
B2: 🔍 EARLY WARNING SIGNS TRACKER — AIDA MARIE RODRIGUEZ
B4: # | C4: Employee Name | D4: Employee ID | E4: Position | F4: Date Hired | G4: Risk Status | H4: Frequent Tardiness | I4: Increased Absences | J4: Low Productivity | K4: Disengagement in Team Huddles | L4: Job Hunting Signals | M4: Conflicts with Teammates | N4: Decline in QA/NPS Scores | O4: Reduced Initiative | P4: Requesting LOA/Leaves | Q4: Withdrawal from Social Activities | R4: With Active CAP? | S4: Risk Score | T4: Rating (Last 3 Mo.) | U4: TL Notes | V4: Last Updated
B5: 1 | C5: Santiago,Annette Patricia | D5: 1526221 | G5: 🟡 YELLOW | H5: NO | I5: NO | J5: NO | K5: NO | L5: NO | M5: NO | N5: NO | O5: NO | P5: NO | Q5: NO | R5: NO | S5: =COUNTIF(H5:R5,"YES") -> 0
B6: 2 | C6: Andujar,Jenny | D6: 1912820 | G6: 🟡 YELLOW | H6: NO | I6: NO | J6: NO | K6: NO | L6: NO | M6: NO | N6: NO | O6: NO | P6: NO | Q6: NO | R6: NO | S6: =COUNTIF(H6:R6,"YES") -> 0
B7: 3 | C7: Rodriguez,Jeannie Ivette | D7: 2061920 | G7: 🟡 YELLOW | H7: NO | I7: NO | J7: NO | K7: NO | L7: NO | M7: NO | N7: NO | O7: NO | P7: NO | Q7: NO | R7: NO | S7: =COUNTIF(H7:R7,"YES") -> 0
B8: 4 | C8: Agosto Sanchez,Gladys Maria | D8: 2064193 | G8: 🟡 YELLOW | H8: NO | I8: NO | J8: NO | K8: NO | L8: NO | M8: NO | N8: NO | O8: NO | P8: NO | Q8: NO | R8: NO | S8: =COUNTIF(H8:R8,"YES") -> 0
B9: 5 | C9: Rodriguez,Rhona | D9: 2066277 | G9: 🟡 YELLOW | H9: NO | I9: NO | J9: NO | K9: NO | L9: NO | M9: NO | N9: NO | O9: NO | P9: NO | Q9: NO | R9: NO | S9: =COUNTIF(H9:R9,"YES") -> 0
B10: 6 | C10: Miranda Cintron,Luis Daniel | D10: 2088201 | G10: 🟡 YELLOW | H10: NO | I10: NO | J10: NO | K10: NO | L10: NO | M10: NO | N10: NO | O10: NO | P10: NO | Q10: NO | R10: NO | S10: =COUNTIF(H10:R10,"YES") -> 0
B11: 7 | C11: Davila-Soto,Stacey N | D11: 2088210 | G11: 🟡 YELLOW | H11: NO | I11: NO | J11: NO | K11: NO | L11: NO | M11: NO | N11: NO | O11: NO | P11: NO | Q11: NO | R11: NO | S11: =COUNTIF(H11:R11,"YES") -> 0
B12: 8 | C12: Siurano,Natassia Krystal | D12: 2249968 | G12: 🟡 YELLOW | H12: NO | I12: NO | J12: NO | K12: NO | L12: NO | M12: NO | N12: NO | O12: NO | P12: NO | Q12: NO | R12: NO | S12: =COUNTIF(H12:R12,"YES") -> 0
B13: 9 | C13: Ramos-Rodriguez,Cristina Michelle | D13: 2253915 | G13: 🟡 YELLOW | H13: NO | I13: NO | J13: NO | K13: NO | L13: NO | M13: NO | N13: NO | O13: NO | P13: NO | Q13: NO | R13: NO | S13: =COUNTIF(H13:R13,"YES") -> 0
B14: 10 | C14: Feliciano,Evelyn | D14: 2254895 | G14: 🟡 YELLOW | H14: NO | I14: NO | J14: NO | K14: NO | L14: NO | M14: NO | N14: NO | O14: NO | P14: NO | Q14: NO | R14: NO | S14: =COUNTIF(H14:R14,"YES") -> 0

Sheet Ailene Logronio Laure
B2: 🔍 EARLY WARNING SIGNS TRACKER — AILENE LOGRONIO LAURE
B4: # | C4: Employee Name | D4: Employee ID | E4: Position | F4: Date Hired | G4: Risk Status | H4: Frequent Tardiness | I4: Increased Absences | J4: Low Productivity | K4: Disengagement in Team Huddles | L4: Job Hunting Signals | M4: Conflicts with Teammates | N4: Decline in QA/NPS Scores | O4: Reduced Initiative | P4: Requesting LOA/Leaves | Q4: Withdrawal from Social Activities | R4: With Active CAP? | S4: Risk Score | T4: Rating (Last 3 Mo.) | U4: TL Notes | V4: Last Updated
B5: 1 | C5: Borgonia,Cesar Medellin | D5: 2119325 | G5: 🟡 YELLOW | H5: NO | I5: NO | J5: NO | K5: NO | L5: NO | M5: NO | N5: NO | O5: NO | P5: NO | Q5: NO | R5: NO | S5: =COUNTIF(H5:R5,"YES") -> 0
B6: 2 | C6: Abul,Jane Savil Allyssa Yap | D6: 2244051 | G6: 🟡 YELLOW | H6: NO | I6: NO | J6: NO | K6: NO | L6: NO | M6: NO | N6: NO | O6: NO | P6: NO | Q6: NO | R6: NO | S6: =COUNTIF(H6:R6,"YES") -> 0
B7: 3 | C7: Astaca An,Jake Potot | D7: 2244267 | G7: 🟡 YELLOW | H7: NO | I7: NO | J7: NO | K7: NO | L7: NO | M7: NO | N7: NO | O7: NO | P7: NO | Q7: NO | R7: NO | S7: =COUNTIF(H7:R7,"YES") -> 0
B8: 4 | C8: Ala,Jalainy Anthony | D8: 900082442 | G8: 🟡 YELLOW | H8: NO | I8: NO | J8: NO | K8: NO | L8: NO | M8: NO | N8: NO | O8: NO | P8: NO | Q8: NO | R8: NO | S8: =COUNTIF(H8:R8,"YES") -> 0
B9: 5 | C9: Nator,Rene | D9: 900127783 | G9: 🟡 YELLOW | H9: NO | I9: NO | J9: NO | K9: NO | L9: NO | M9: NO | N9: NO | O9: NO | P9: NO | Q9: NO | R9: NO | S9: =COUNTIF(H9:R9,"YES") -> 0
B10: 6 | C10: Anora,Chalpretch Elija | D10: 900127842 | G10: 🟡 YELLOW | H10: NO | I10: NO | J10: NO | K10: NO | L10: NO | M10: NO | N10: NO | O10: NO | P10: NO | Q10: NO | R10: NO | S10: =COUNTIF(H10:R10,"YES") -> 0
B11: 7 | C11: Gumatay,Mary Jeil Twixy | D11: 900127878 | G11: 🟡 YELLOW | H11: NO | I11: NO | J11: NO | K11: NO | L11: NO | M11: NO | N11: NO | O11: NO | P11: NO | Q11: NO | R11: NO | S11: =COUNTIF(H11:R11,"YES") -> 0
B12: 8 | C12: Jumao-As,Christian Dominique | D12: 900127896 | G12: 🟡 YELLOW | H12: NO | I12: NO | J12: NO | K12: NO | L12: NO | M12: NO | N12: NO | O12: NO | P12: NO | Q12: NO | R12: NO | S12: =COUNTIF(H12:R12,"YES") -> 0
B13: 9 | C13: Pamisa,Marjorie | D13: 900128185 | G13: 🟡 YELLOW | H13: NO | I13: NO | J13: NO | K13: NO | L13: NO | M13: NO | N13: NO | O13: NO | P13: NO | Q13: NO | R13: NO | S13: =COUNTIF(H13:R13,"YES") -> 0
B14: 10 | C14: Giducos,Christy Mae | D14: 900128216 | G14: 🟡 YELLOW | H14: NO | I14: NO | J14: NO | K14: NO | L14: NO | M14: NO | N14: NO | O14: NO | P14: NO | Q14: NO | R14: NO | S14: =COUNTIF(H14:R14,"YES") -> 0
B15: 11 | C15: Singson,Chineelyn Mae | D15: 900128566 | G15: 🟡 YELLOW | H15: NO | I15: NO | J15: NO | K15: NO | L15: NO | M15: NO | N15: NO | O15: NO | P15: NO | Q15: NO | R15: NO | S15: =COUNTIF(H15:R15,"YES") -> 0
B16: 12 | C16: Omambac,Redje | D16: 900128667 | G16: 🟡 YELLOW | H16: NO | I16: NO | J16: NO | K16: NO | L16: NO | M16: NO | N16: NO | O16: NO | P16: NO | Q16: NO | R16: NO | S16: =COUNTIF(H16:R16,"YES") -> 0
... B22: 18 | C22: Inot,Rebecca | D22: 900130682 | G22: 🟡 YELLOW | H22: NO | I22: NO | J22: NO | K22: NO | L22: NO | M22: NO | N22: NO | O22: NO | P22: NO | Q22: NO | R22: NO | S22: =COUNTIF(H22:R22,"YES") -> 0

Sheet Alanie Sanchez Lapuz
B2: 🔍 EARLY WARNING SIGNS TRACKER — ALANIE SANCHEZ LAPUZ
B4: # | C4: Employee Name | D4: Employee ID | E4: Position | F4: Date Hired | G4: Risk Status | H4: Frequent Tardiness | I4: Increased Absences | J4: Low Productivity | K4: Disengagement in Team Huddles | L4: Job Hunting Signals | M4: Conflicts with Teammates | N4: Decline in QA/NPS Scores | O4: Reduced Initiative | P4: Requesting LOA/Leaves | Q4: Withdrawal from Social Activities | R4: With Active CAP? | S4: Risk Score | T4: Rating (Last 3 Mo.) | U4: TL Notes | V4: Last Updated
B5: 1 | C5: Chaves,Rhea Fariola | D5: 895913 | G5: 🟡 YELLOW | H5: NO | I5: NO | J5: NO | K5: NO | L5: NO | M5: NO | N5: NO | O5: NO | P5: NO | Q5: NO | R5: NO | S5: =COUNTIF(H5:R5,"YES") -> 0
B6: 2 | C6: Dacanay,Paolo Cabantog | D6: 1073247 | G6: 🟡 YELLOW | H6: NO | I6: NO | J6: NO | K6: NO | L6: NO | M6: NO | N6: NO | O6: NO | P6: NO | Q6: NO | R6: NO | S6: =COUNTIF(H6:R6,"YES") -> 0
B7: 3 | C7: Calupig,Charmaine Garde | D7: 1126814 | G7: 🟡 YELLOW | H7: NO | I7: NO | J7: NO | K7: NO | L7: NO | M7: NO | N7: NO | O7: NO | P7: NO | Q7: NO | R7: NO | S7: =COUNTIF(H7:R7,"YES") -> 0
B8: 4 | C8: Ballesteros,Joseph Andrew Cera | D8: 1183689 | G8: 🟡 YELLOW | H8: NO | I8: NO | J8: NO | K8: NO | L8: NO | M8: NO | N8: NO | O8: NO | P8: NO | Q8: NO | R8: NO | S8: =COUNTIF(H8:R8,"YES") -> 0
B9: 5 | C9: Manalaysay,Abigael Singcol | D9: 1398913 | G9: 🟡 YELLOW | H9: NO | I9: NO | J9: NO | K9: NO | L9: NO | M9: NO | N9: NO | O9: NO | P9: NO | Q9: NO | R9: NO | S9: =COUNTIF(H9:R9,"YES") -> 0

Sheet Alyana Marie Jose Dela Cruz
B2: 🔍 EARLY WARNING SIGNS TRACKER — ALYANA MARIE JOSE DELA CRUZ
B4: # | C4: Employee Name | D4: Employee ID | E4: Position | F4: Date Hired | G4: Risk Status | H4: Frequent Tardiness | I4: Increased Absences | J4: Low Productivity | K4: Disengagement in Team Huddles | L4: Job Hunting Signals | M4: Conflicts with Teammates | N4: Decline in QA/NPS Scores | O4: Reduced Initiative | P4: Requesting LOA/Leaves | Q4: Withdrawal from Social Activities | R4: With Active CAP? | S4: Risk Score | T4: Rating (Last 3 Mo.) | U4: TL Notes | V4: Last Updated
B5: 1 | C5: Falsis,Cyrus Hope Banot | D5: 1285305 | G5: 🟡 YELLOW | H5: NO | I5: NO | J5: NO | K5: NO | L5: NO | M5: NO | N5: NO | O5: NO | P5: NO | Q5: NO | R5: NO | S5: =COUNTIF(H5:R5,"YES") -> 0
B6: 2 | C6: Pogado,Maria Christina Abenir | D6: 1743256 | G6: 🟡 YELLOW | H6: NO | I6: NO | J6: NO | K6: NO | L6: NO | M6: NO | N6: NO | O6: NO | P6: NO | Q6: NO | R6: NO | S6: =COUNTIF(H6:R6,"YES") -> 0
B7: 3 | C7: Bolinao,Joseph Nikko Paz | D7: 1922793 | G7: 🟡 YELLOW | H7: NO | I7: NO | J7: NO | K7: NO | L7: NO | M7: NO | N7: NO | O7: NO | P7: NO | Q7: NO | R7: NO | S7: =COUNTIF(H7:R7,"YES") -> 0
B8: 4 | C8: Canares,Bunce Reno | D8: 1938955 | G8: 🟡 YELLOW | H8: NO | I8: NO | J8: NO | K8: NO | L8: NO | M8: NO | N8: NO | O8: NO | P8: NO | Q8: NO | R8: NO | S8: =COUNTIF(H8:R8,"YES") -> 0
B9: 5 | C9: Brioso,Denisse Rosero | D9: 1958905 | G9: 🟡 YELLOW | H9: NO | I9: NO | J9: NO | K9: NO | L9: NO | M9: NO | N9: NO | O9: NO | P9: NO | Q9: NO | R9: NO | S9: =COUNTIF(H9:R9,"YES") -> 0
B10: 6 | C10: Flores,Ezra Marie Padilla | D10: 2109623 | G10: 🟡 YELLOW | H10: NO | I10: NO | J10: NO | K10: NO | L10: NO | M10: NO | N10: NO | O10: NO | P10: NO | Q10: NO | R10: NO | S10: =COUNTIF(H10:R10,"YES") -> 0
B11: 7 | C11: Calma,Princess Pelipada | D11: 2111614 | G11: 🟡 YELLOW | H11: NO | I11: NO | J11: NO | K11: NO | L11: NO | M11: NO | N11: NO | O11: NO | P11: NO | Q11: NO | R11: NO | S11: =COUNTIF(H11:R11,"YES") -> 0
B12: 8 | C12: Ocampo,Erwin Ponciano | D12: 2116291 | G12: 🟡 YELLOW | H12: NO | I12: NO | J12: NO | K12: NO | L12: NO | M12: NO | N12: NO | O12: NO | P12: NO | Q12: NO | R12: NO | S12: =COUNTIF(H12:R12,"YES") -> 0
B13: 9 | C13: Ortiz,Josephine Sinangote | D13: 2148943 | G13: 🟡 YELLOW | H13: NO | I13: NO | J13: NO | K13: NO | L13: NO | M13: NO | N13: NO | O13: NO | P13: NO | Q13: NO | R13: NO | S13: =COUNTIF(H13:R13,"YES") -> 0
B14: 10 | C14: Cañad,Sepora Villaflores | D14: 2236081 | G14: 🟡 YELLOW | H14: NO | I14: NO | J14: NO | K14: NO | L14: NO | M14: NO | N14: NO | O14: NO | P14: NO | Q14: NO | R14: NO | S14: =COUNTIF(H14:R14,"YES") -> 0
B15: 11 | C15: Bato,Arnel Sulatorio | D15: 2258037 | G15: 🟡 YELLOW | H15: NO | I15: NO | J15: NO | K15: NO | L15: NO | M15: NO | N15: NO | O15: NO | P15: NO | Q15: NO | R15: NO | S15: =COUNTIF(H15:R15,"YES") -> 0
B16: 12 | C16: Dabalos,Shella Sipalay | D16: 2258517 | G16: 🟡 YELLOW | H16: NO | I16: NO | J16: NO | K16: NO | L16: NO | M16: NO | N16: NO | O16: NO | P16: NO | Q16: NO | R16: NO | S16: =COUNTIF(H16:R16,"YES") -> 0
... B28: 24 | C28: Rivera,Cherlhyn Anne | D28: 900130098 | G28: 🟡 YELLOW | H28: NO | I28: NO | J28: NO | K28: NO | L28: NO | M28: NO | N28: NO | O28: NO | P28: NO | Q28: NO | R28: NO | S28: =COUNTIF(H28:R28,"YES") -> 0

Sheet Archiene Ross Calderon Herbias
B2: 🔍 EARLY WARNING SIGNS TRACKER — ARCHIENE ROSS CALDERON HERBIAS
B4: # | C4: Employee Name | D4: Employee ID | E4: Position | F4: Date Hired | G4: Risk Status | H4: Frequent Tardiness | I4: Increased Absences | J4: Low Productivity | K4: Disengagement in Team Huddles | L4: Job Hunting Signals | M4: Conflicts with Teammates | N4: Decline in QA/NPS Scores | O4: Reduced Initiative | P4: Requesting LOA/Leaves | Q4: Withdrawal from Social Activities | R4: With Active CAP? | S4: Risk Score | T4: Rating (Last 3 Mo.) | U4: TL Notes | V4: Last Updated
B5: 1 | C5: Perez,Gwen Kristina Ebardo | D5: 1939520 | G5: 🟡 YELLOW | H5: NO | I5: NO | J5: NO | K5: NO | L5: NO | M5: NO | N5: NO | O5: NO | P5: NO | Q5: NO | R5: NO | S5: =COUNTIF(H5:R5,"YES") -> 0
B6: 2 | C6: De Los Santos,Phoebe Hannah Apara | D6: 1943508 | G6: 🟡 YELLOW | H6: NO | I6: NO | J6: NO | K6: NO | L6: NO | M6: NO | N6: NO | O6: NO | P6: NO | Q6: NO | R6: NO | S6: =COUNTIF(H6:R6,"YES") -> 0
B7: 3 | C7: Guilipa,Ma Lexy Jean Ucab | D7: 2108438 | G7: 🟡 YELLOW | H7: NO | I7: NO | J7: NO | K7: NO | L7: NO | M7: NO | N7: NO | O7: NO | P7: NO | Q7: NO | R7: NO | S7: =COUNTIF(H7:R7,"YES") -> 0
B8: 4 | C8: Paciñ,Princess Jean Menor | D8: 2232915 | G8: 🟡 YELLOW | H8: NO | I8: NO | J8: NO | K8: NO | L8: NO | M8: NO | N8: NO | O8: NO | P8: NO | Q8: NO | R8: NO | S8: =COUNTIF(H8:R8,"YES") -> 0
B9: 5 | C9: Aniban,Brandon Saludaga | D9: 2233004 | G9: 🟡 YELLOW | H9: NO | I9: NO | J9: NO | K9: NO | L9: NO | M9: NO | N9: NO | O9: NO | P9: NO | Q9: NO | R9: NO | S9: =COUNTIF(H9:R9,"YES") -> 0
B10: 6 | C10: Bureros,Jaybee Benigay | D10: 2235984 | G10: 🟡 YELLOW | H10: NO | I10: NO | J10: NO | K10: NO | L10: NO | M10: NO | N10: NO | O10: NO | P10: NO | Q10: NO | R10: NO | S10: =COUNTIF(H10:R10,"YES") -> 0
B11: 7 | C11: Abueva,Lovely Mae Canizar | D11: 2236076 | G11: 🟡 YELLOW | H11: NO | I11: NO | J11: NO | K11: NO | L11: NO | M11: NO | N11: NO | O11: NO | P11: NO | Q11: NO | R11: NO | S11: =COUNTIF(H11:R11,"YES") -> 0
B12: 8 | C12: Suson,Lurraine | D12: 2238298 | G12: 🟡 YELLOW | H12: NO | I12: NO | J12: NO | K12: NO | L12: NO | M12: NO | N12: NO | O12: NO | P12: NO | Q12: NO | R12: NO | S12: =COUNTIF(H12:R12,"YES") -> 0
B13: 9 | C13: Atendido,Kristelle Calamdag | D13: 2244256 | G13: 🟡 YELLOW | H13: NO | I13: NO | J13: NO | K13: NO | L13: NO | M13: NO | N13: NO | O13: NO | P13: NO | Q13: NO | R13: NO | S13: =COUNTIF(H13:R13,"YES") -> 0
B14: 10 | C14: Rafaela,John Vert Cabato | D14: 2245220 | G14: 🟡 YELLOW | H14: NO | I14: NO | J14: NO | K14: NO | L14: NO | M14: NO | N14: NO | O14: NO | P14: NO | Q14: NO | R14: NO | S14: =COUNTIF(H14:R14,"YES") -> 0
B15: 11 | C15: Nepomuceno,Kristine Jay Ann | D15: 900040071 | G15: 🟡 YELLOW | H15: NO | I15: NO | J15: NO | K15: NO | L15: NO | M15: NO | N15: NO | O15: NO | P15: NO | Q15: NO | R15: NO | S15: =COUNTIF(H15:R15,"YES") -> 0
B16: 12 | C16: Trinidad,Jill Rondina | D16: 900040082 | G16: 🟡 YELLOW | H16: NO | I16: NO | J16: NO | K16: NO | L16: NO | M16: NO | N16: NO | O16: NO | P16: NO | Q16: NO | R16: NO | S16: =COUNTIF(H16:R16,"YES") -> 0
... B22: 18 | C22: Radaza,Alvingie | D22: 900062114 | G22: 🟡 YELLOW | H22: NO | I22: NO | J22: NO | K22: NO | L22: NO | M22: NO | N22: NO | O22: NO | P22: NO | Q22: NO | R22: NO | S22: =COUNTIF(H22:R22,"YES") -> 0

Sheet Beulah Grace Arroyo Dacanay
B2: 🔍 EARLY WARNING SIGNS TRACKER — BEULAH GRACE ARROYO DACANAY
B4: # | C4: Employee Name | D4: Employee ID | E4: Position | F4: Date Hired | G4: Risk Status | H4: Frequent Tardiness | I4: Increased Absences | J4: Low Productivity | K4: Disengagement in Team Huddles | L4: Job Hunting Signals | M4: Conflicts with Teammates | N4: Decline in QA/NPS Scores | O4: Reduced Initiative | P4: Requesting LOA/Leaves | Q4: Withdrawal from Social Activities | R4: With Active CAP? | S4: Risk Score | T4: Rating (Last 3 Mo.) | U4: TL Notes | V4: Last Updated
B5: 1 | C5: Villamor,Arnel Villanueva | D5: 2125325 | G5: 🟡 YELLOW | H5: NO | I5: NO | J5: NO | K5: NO | L5: NO | M5: NO | N5: NO | O5: NO | P5: NO | Q5: NO | R5: NO | S5: =COUNTIF(H5:R5,"YES") -> 0
B6: 2 | C6: Bautista,Irene | D6: 2130135 | G6: 🟡 YELLOW | H6: NO | I6: NO | J6: NO | K6: NO | L6: NO | M6: NO | N6: NO | O6: NO | P6: NO | Q6: NO | R6: NO | S6: =COUNTIF(H6:R6,"YES") -> 0
B7: 3 | C7: Aboganda,Glylen Jay Basada | D7: 2149643 | G7: 🟡 YELLOW | H7: NO | I7: NO | J7: NO | K7: NO | L7: NO | M7: NO | N7: NO | O7: NO | P7: NO | Q7: NO | R7: NO | S7: =COUNTIF(H7:R7,"YES") -> 0
B8: 4 | C8: Nudalo,Yvette Pacaldo | D8: 2238244 | G8: 🟡 YELLOW | H8: NO | I8: NO | J8: NO | K8: NO | L8: NO | M8: NO | N8: NO | O8: NO | P8: NO | Q8: NO | R8: NO | S8: =COUNTIF(H8:R8,"YES") -> 0
B9: 5 | C9: Taburnal,Godfrey Justan | D9: 2254055 | G9: 🟡 YELLOW | H9: NO | I9: NO | J9: NO | K9: NO | L9: NO | M9: NO | N9: NO | O9: NO | P9: NO | Q9: NO | R9: NO | S9: =COUNTIF(H9:R9,"YES") -> 0
B10: 6 | C10: Gudarido,Cherry Mae Tortugo | D10: 2258536 | G10: 🟡 YELLOW | H10: NO | I10: NO | J10: NO | K10: NO | L10: NO | M10: NO | N10: NO | O10: NO | P10: NO | Q10: NO | R10: NO | S10: =COUNTIF(H10:R10,"YES") -> 0
B11: 7 | C11: Dicdiquin,Analyn Auditor | D11: 2258550 | G11: 🟡 YELLOW | H11: NO | I11: NO | J11: NO | K11: NO | L11: NO | M11: NO | N11: NO | O11: NO | P11: NO | Q11: NO | R11: NO | S11: =COUNTIF(H11:R11,"YES") -> 0
B12: 8 | C12: Angayao,Janiel James | D12: 900041310 | G12: 🟡 YELLOW | H12: NO | I12: NO | J12: NO | K12: NO | L12: NO | M12: NO | N12: NO | O12: NO | P12: NO | Q12: NO | R12: NO | S12: =COUNTIF(H12:R12,"YES") -> 0
B13: 9 | C13: Remosil ,Kyle Vincent | D13: 900041320 | G13: 🟡 YELLOW | H13: NO | I13: NO | J13: NO | K13: NO | L13: NO | M13: NO | N13: NO | O13: NO | P13: NO | Q13: NO | R13: NO | S13: =COUNTIF(H13:R13,"YES") -> 0
B14: 10 | C14: Malaran ,Rennel | D14: 900047355 | G14: 🟡 YELLOW | H14: NO | I14: NO | J14: NO | K14: NO | L14: NO | M14: NO | N14: NO | O14: NO | P14: NO | Q14: NO | R14: NO | S14: =COUNTIF(H14:R14,"YES") -> 0
B15: 11 | C15: Fedillaga,Jean Clarette | D15: 900062127 | G15: 🟡 YELLOW | H15: NO | I15: NO | J15: NO | K15: NO | L15: NO | M15: NO | N15: NO | O15: NO | P15: NO | Q15: NO | R15: NO | S15: =COUNTIF(H15:R15,"YES") -> 0
B16: 12 | C16: Lao,Patricia | D16: 900062436 | G16: 🟡 YELLOW | H16: NO | I16: NO | J16: NO | K16: NO | L16: NO | M16: NO | N16: NO | O16: NO | P16: NO | Q16: NO | R16: NO | S16: =COUNTIF(H16:R16,"YES") -> 0
... B23: 19 | C23: Getaruelas,Rogelson | D23: 900098991 | G23: 🟡 YELLOW | H23: NO | I23: NO | J23: NO | K23: NO | L23: NO | M23: NO | N23: NO | O23: NO | P23: NO | Q23: NO | R23: NO | S23: =COUNTIF(H23:R23,"YES") -> 0

Sheet Carlo Angelo Lim Regalado
B2: 🔍 EARLY WARNING SIGNS TRACKER — CARLO ANGELO LIM REGALADO
B4: # | C4: Employee Name | D4: Employee ID | E4: Position | F4: Date Hired | G4: Risk Status | H4: Frequent Tardiness | I4: Increased Absences | J4: Low Productivity | K4: Disengagement in Team Huddles | L4: Job Hunting Signals | M4: Conflicts with Teammates | N4: Decline in QA/NPS Scores | O4: Reduced Initiative | P4: Requesting LOA/Leaves | Q4: Withdrawal from Social Activities | R4: With Active CAP? | S4: Risk Score | T4: Rating (Last 3 Mo.) | U4: TL Notes | V4: Last Updated
B5: 1 | C5: Laure,Ailene Logronio | D5: 1045068 | G5: 🟡 YELLOW | H5: NO | I5: NO | J5: NO | K5: NO | L5: NO | M5: NO | N5: NO | O5: NO | P5: NO | Q5: NO | R5: NO | S5: =COUNTIF(H5:R5,"YES") -> 0
B6: 2 | C6: Herbias,Archiene Ross Calderon | D6: 1834949 | G6: 🟡 YELLOW | H6: NO | I6: NO | J6: NO | K6: NO | L6: NO | M6: NO | N6: NO | O6: NO | P6: NO | Q6: NO | R6: NO | S6: =COUNTIF(H6:R6,"YES") -> 0
B7: 3 | C7: Comendador,Leou Alven Narito | D7: 1895222 | G7: 🟡 YELLOW | H7: NO | I7: NO | J7: NO | K7: NO | L7: NO | M7: NO | N7: NO | O7: NO | P7: NO | Q7: NO | R7: NO | S7: =COUNTIF(H7:R7,"YES") -> 0
B8: 4 | C8: Alvaro,Cres Marvin Alexander | D8: 1988888 | G8: 🟡 YELLOW | H8: NO | I8: NO | J8: NO | K8: NO | L8: NO | M8: NO | N8: NO | O8: NO | P8: NO | Q8: NO | R8: NO | S8: =COUNTIF(H8:R8,"YES") -> 0

Sheet Cathreen Aizha Ria Almazan
B2: 🔍 EARLY WARNING SIGNS TRACKER — CATHREEN AIZHA RIA ALMAZAN
B4: # | C4: Employee Name | D4: Employee ID | E4: Position | F4: Date Hired | G4: Risk Status | H4: Frequent Tardiness | I4: Increased Absences | J4: Low Productivity | K4: Disengagement in Team Huddles | L4: Job Hunting Signals | M4: Conflicts with Teammates | N4: Decline in QA/NPS Scores | O4: Reduced Initiative | P4: Requesting LOA/Leaves | Q4: Withdrawal from Social Activities | R4: With Active CAP? | S4: Risk Score | T4: Rating (Last 3 Mo.) | U4: TL Notes | V4: Last Updated
B5: 1 | C5: Regalado,Carlo Angelo Lim | D5: 957496 | G5: 🟡 YELLOW | H5: NO | I5: NO | J5: NO | K5: NO | L5: NO | M5: NO | N5: NO | O5: NO | P5: NO | Q5: NO | R5: NO | S5: =COUNTIF(H5:R5,"YES") -> 0
B6: 2 | C6: Lapuz,Alanie Sanchez | D6: 1186681 | G6: 🟡 YELLOW | H6: NO | I6: NO | J6: NO | K6: NO | L6: NO | M6: NO | N6: NO | O6: NO | P6: NO | Q6: NO | R6: NO | S6: =COUNTIF(H6:R6,"YES") -> 0
B7: 3 | C7: Tuting,Frederic Matthew Carlos | D7: 1291775 | G7: 🟡 YELLOW | H7: NO | I7: NO | J7: NO | K7: NO | L7: NO | M7: NO | N7: NO | O7: NO | P7: NO | Q7: NO | R7: NO | S7: =COUNTIF(H7:R7,"YES") -> 0
B8: 4 | C8: Rudila,Janice Carbonilla | D8: 1485076 | G8: 🟡 YELLOW | H8: NO | I8: NO | J8: NO | K8: NO | L8: NO | M8: NO | N8: NO | O8: NO | P8: NO | Q8: NO | R8: NO | S8: =COUNTIF(H8:R8,"YES") -> 0

Sheet Charlie Jr De Asis Cuartero
B2: 🔍 EARLY WARNING SIGNS TRACKER — CHARLIE JR DE ASIS CUARTERO
B4: # | C4: Employee Name | D4: Employee ID | E4: Position | F4: Date Hired | G4: Risk Status | H4: Frequent Tardiness | I4: Increased Absences | J4: Low Productivity | K4: Disengagement in Team Huddles | L4: Job Hunting Signals | M4: Conflicts with Teammates | N4: Decline in QA/NPS Scores | O4: Reduced Initiative | P4: Requesting LOA/Leaves | Q4: Withdrawal from Social Activities | R4: With Active CAP? | S4: Risk Score | T4: Rating (Last 3 Mo.) | U4: TL Notes | V4: Last Updated
B5: 1 | C5: Cabuenas,Paula Joy Diaz | D5: 1130605 | G5: 🟡 YELLOW | H5: NO | I5: NO | J5: NO | K5: NO | L5: NO | M5: NO | N5: NO | O5: NO | P5: NO | Q5: NO | R5: NO | S5: =COUNTIF(H5:R5,"YES") -> 0
B6: 2 | C6: Nares,Vincent Gualdada | D6: 1180052 | G6: 🟡 YELLOW | H6: NO | I6: NO | J6: NO | K6: NO | L6: NO | M6: NO | N6: NO | O6: NO | P6: NO | Q6: NO | R6: NO | S6: =COUNTIF(H6:R6,"YES") -> 0
B7: 3 | C7: Demdam,Sheena Sales | D7: 1304362 | G7: 🟡 YELLOW | H7: NO | I7: NO | J7: NO | K7: NO | L7: NO | M7: NO | N7: NO | O7: NO | P7: NO | Q7: NO | R7: NO | S7: =COUNTIF(H7:R7,"YES") -> 0
B8: 4 | C8: Esperat,Orlando Jr Ignacio | D8: 1364822 | G8: 🟡 YELLOW | H8: NO | I8: NO | J8: NO | K8: NO | L8: NO | M8: NO | N8: NO | O8: NO | P8: NO | Q8: NO | R8: NO | S8: =COUNTIF(H8:R8,"YES") -> 0
B9: 5 | C9: Diligencia,Eunice Datar | D9: 1626237 | G9: 🟡 YELLOW | H9: NO | I9: NO | J9: NO | K9: NO | L9: NO | M9: NO | N9: NO | O9: NO | P9: NO | Q9: NO | R9: NO | S9: =COUNTIF(H9:R9,"YES") -> 0
B10: 6 | C10: Tejada,Gregorio Jr Iii Gallego | D10: 1627458 | G10: 🟡 YELLOW | H10: NO | I10: NO | J10: NO | K10: NO | L10: NO | M10: NO | N10: NO | O10: NO | P10: NO | Q10: NO | R10: NO | S10: =COUNTIF(H10:R10,"YES") -> 0
B11: 7 | C11: Dela Cruz,Carl Dominic | D11: 1910787 | G11: 🟡 YELLOW | H11: NO | I11: NO | J11: NO | K11: NO | L11: NO | M11: NO | N11: NO | O11: NO | P11: NO | Q11: NO | R11: NO | S11: =COUNTIF(H11:R11,"YES") -> 0
B12: 8 | C12: Khalifa,Adnan Raymundo | D12: 1919948 | G12: 🟡 YELLOW | H12: NO | I12: NO | J12: NO | K12: NO | L12: NO | M12: NO | N12: NO | O12: NO | P12: NO | Q12: NO | R12: NO | S12: =COUNTIF(H12:R12,"YES") -> 0
B13: 9 | C13: Bernardez,Paolo Angelo Claveria | D13: 1958881 | G13: 🟡 YELLOW | H13: NO | I13: NO | J13: NO | K13: NO | L13: NO | M13: NO | N13: NO | O13: NO | P13: NO | Q13: NO | R13: NO | S13: =COUNTIF(H13:R13,"YES") -> 0
B14: 10 | C14: Ortega,Olivia Noren Portacio | D14: 900031814 | G14: 🟡 YELLOW | H14: NO | I14: NO | J14: NO | K14: NO | L14: NO | M14: NO | N14: NO | O14: NO | P14: NO | Q14: NO | R14: NO | S14: =COUNTIF(H14:R14,"YES") -> 0
B15: 11 | C15: Satiembre,Joppa Mae Gomura | D15: 900033211 | G15: 🟡 YELLOW | H15: NO | I15: NO | J15: NO | K15: NO | L15: NO | M15: NO | N15: NO | O15: NO | P15: NO | Q15: NO | R15: NO | S15: =COUNTIF(H15:R15,"YES") -> 0
B16: 12 | C16: Estacio,John Khristoffer | D16: 900033222 | G16: 🟡 YELLOW | H16: NO | I16: NO | J16: NO | K16: NO | L16: NO | M16: NO | N16: NO | O16: NO | P16: NO | Q16: NO | R16: NO | S16: =COUNTIF(H16:R16,"YES") -> 0
... B18: 14 | C18: Galit,Drex Lester Ene | D18: 900038990 | G18: 🟡 YELLOW | H18: NO | I18: NO | J18: NO | K18: NO | L18: NO | M18: NO | N18: NO | O18: NO | P18: NO | Q18: NO | R18: NO | S18: =COUNTIF(H18:R18,"YES") -> 0

Sheet Charmaine Garde Calupig
B2: 🔍 EARLY WARNING SIGNS TRACKER — CHARMAINE GARDE CALUPIG
B4: # | C4: Employee Name | D4: Employee ID | E4: Position | F4: Date Hired | G4: Risk Status | H4: Frequent Tardiness | I4: Increased Absences | J4: Low Productivity | K4: Disengagement in Team Huddles | L4: Job Hunting Signals | M4: Conflicts with Teammates | N4: Decline in QA/NPS Scores | O4: Reduced Initiative | P4: Requesting LOA/Leaves | Q4: Withdrawal from Social Activities | R4: With Active CAP? | S4: Risk Score | T4: Rating (Last 3 Mo.) | U4: TL Notes | V4: Last Updated
B5: 1 | C5: Dumalag,Maria Luisa Mercado | D5: 1181770 | G5: 🟡 YELLOW | H5: NO | I5: NO | J5: NO | K5: NO | L5: NO | M5: NO | N5: NO | O5: NO | P5: NO | Q5: NO | R5: NO | S5: =COUNTIF(H5:R5,"YES") -> 0
B6: 2 | C6: Macasero,Hazel Matos | D6: 1249865 | G6: 🟡 YELLOW | H6: NO | I6: NO | J6: NO | K6: NO | L6: NO | M6: NO | N6: NO | O6: NO | P6: NO | Q6: NO | R6: NO | S6: =COUNTIF(H6:R6,"YES") -> 0
B7: 3 | C7: Lacida,Princess Aileen Delloson | D7: 1365554 | G7: 🟡 YELLOW | H7: NO | I7: NO | J7: NO | K7: NO | L7: NO | M7: NO | N7: NO | O7: NO | P7: NO | Q7: NO | R7: NO | S7: =COUNTIF(H7:R7,"YES") -> 0
B8: 4 | C8: Alasaas,Mark Anthony Espigar | D8: 1384153 | G8: 🟡 YELLOW | H8: NO | I8: NO | J8: NO | K8: NO | L8: NO | M8: NO | N8: NO | O8: NO | P8: NO | Q8: NO | R8: NO | S8: =COUNTIF(H8:R8,"YES") -> 0
B9: 5 | C9: Delos Reyes,Jhorelle Lerona | D9: 1398901 | G9: 🟡 YELLOW | H9: NO | I9: NO | J9: NO | K9: NO | L9: NO | M9: NO | N9: NO | O9: NO | P9: NO | Q9: NO | R9: NO | S9: =COUNTIF(H9:R9,"YES") -> 0
B10: 6 | C10: Lawas,Romel John Ferrero | D10: 1521923 | G10: 🟡 YELLOW | H10: NO | I10: NO | J10: NO | K10: NO | L10: NO | M10: NO | N10: NO | O10: NO | P10: NO | Q10: NO | R10: NO | S10: =COUNTIF(H10:R10,"YES") -> 0
B11: 7 | C11: Lagrimas,Harold James Aguillon | D11: 1522576 | G11: 🟡 YELLOW | H11: NO | I11: NO | J11: NO | K11: NO | L11: NO | M11: NO | N11: NO | O11: NO | P11: NO | Q11: NO | R11: NO | S11: =COUNTIF(H11:R11,"YES") -> 0
B12: 8 | C12: Perez,Joyce Ann Elisan | D12: 1748546 | G12: 🟡 YELLOW | H12: NO | I12: NO | J12: NO | K12: NO | L12: NO | M12: NO | N12: NO | O12: NO | P12: NO | Q12: NO | R12: NO | S12: =COUNTIF(H12:R12,"YES") -> 0
B13: 9 | C13: Macarilay,Jean | D13: 1907247 | G13: 🟡 YELLOW | H13: NO | I13: NO | J13: NO | K13: NO | L13: NO | M13: NO | N13: NO | O13: NO | P13: NO | Q13: NO | R13: NO | S13: =COUNTIF(H13:R13,"YES") -> 0
B14: 10 | C14: Pelicano,Janjejoyce Alvez | D14: 1958931 | G14: 🟡 YELLOW | H14: NO | I14: NO | J14: NO | K14: NO | L14: NO | M14: NO | N14: NO | O14: NO | P14: NO | Q14: NO | R14: NO | S14: =COUNTIF(H14:R14,"YES") -> 0
B15: 11 | C15: Villanueva,Carmina Minorca | D15: 2133869 | G15: 🟡 YELLOW | H15: NO | I15: NO | J15: NO | K15: NO | L15: NO | M15: NO | N15: NO | O15: NO | P15: NO | Q15: NO | R15: NO | S15: =COUNTIF(H15:R15,"YES") -> 0
B16: 12 | C16: Dayrit,Jon Paolo Jao | D16: 2159060 | G16: 🟡 YELLOW | H16: NO | I16: NO | J16: NO | K16: NO | L16: NO | M16: NO | N16: NO | O16: NO | P16: NO | Q16: NO | R16: NO | S16: =COUNTIF(H16:R16,"YES") -> 0
B17: 13 | C17: Rosello,James Bembo | D17: 900068394 | G17: 🟡 YELLOW | H17: NO | I17: NO | J17: NO | K17: NO | L17: NO | M17: NO | N17: NO | O17: NO | P17: NO | Q17: NO | R17: NO | S17: =COUNTIF(H17:R17,"YES") -> 0

Sheet Chrisel Lingat Martinez
B2: 🔍 EARLY WARNING SIGNS TRACKER — CHRISEL LINGAT MARTINEZ
B4: # | C4: Employee Name | D4: Employee ID | E4: Position | F4: Date Hired | G4: Risk Status | H4: Frequent Tardiness | I4: Increased Absences | J4: Low Productivity | K4: Disengagement in Team Huddles | L4: Job Hunting Signals | M4: Conflicts with Teammates | N4: Decline in QA/NPS Scores | O4: Reduced Initiative | P4: Requesting LOA/Leaves | Q4: Withdrawal from Social Activities | R4: With Active CAP? | S4: Risk Score | T4: Rating (Last 3 Mo.) | U4: TL Notes | V4: Last Updated
B5: 1 | C5: Zablan,Emmanuel Laguilles | D5: 1014806 | G5: 🟡 YELLOW | H5: NO | I5: NO | J5: NO | K5: NO | L5: NO | M5: NO | N5: NO | O5: NO | P5: NO | Q5: NO | R5: NO | S5: =COUNTIF(H5:R5,"YES") -> 0
B6: 2 | C6: Tilbe,Angielyn Yap | D6: 1046283 | G6: 🟡 YELLOW | H6: NO | I6: NO | J6: NO | K6: NO | L6: NO | M6: NO | N6: NO | O6: NO | P6: NO | Q6: NO | R6: NO | S6: =COUNTIF(H6:R6,"YES") -> 0
B7: 3 | C7: Flores,Jan Michael Enciso | D7: 1081100 | G7: 🟡 YELLOW | H7: NO | I7: NO | J7: NO | K7: NO | L7: NO | M7: NO | N7: NO | O7: NO | P7: NO | Q7: NO | R7: NO | S7: =COUNTIF(H7:R7,"YES") -> 0
B8: 4 | C8: Magpusao,Mariecris Villarete | D8: 1087050 | G8: 🟡 YELLOW | H8: NO | I8: NO | J8: NO | K8: NO | L8: NO | M8: NO | N8: NO | O8: NO | P8: NO | Q8: NO | R8: NO | S8: =COUNTIF(H8:R8,"YES") -> 0
B9: 5 | C9: Palma,Michael Richard Infante | D9: 1164811 | G9: 🟡 YELLOW | H9: NO | I9: NO | J9: NO | K9: NO | L9: NO | M9: NO | N9: NO | O9: NO | P9: NO | Q9: NO | R9: NO | S9: =COUNTIF(H9:R9,"YES") -> 0
B10: 6 | C10: Daileg,Kristine Dianne Evangelista | D10: 1164877 | G10: 🟡 YELLOW | H10: NO | I10: NO | J10: NO | K10: NO | L10: NO | M10: NO | N10: NO | O10: NO | P10: NO | Q10: NO | R10: NO | S10: =COUNTIF(H10:R10,"YES") -> 0
B11: 7 | C11: Gaviola,Lester Torno | D11: 1249049 | G11: 🟡 YELLOW | H11: NO | I11: NO | J11: NO | K11: NO | L11: NO | M11: NO | N11: NO | O11: NO | P11: NO | Q11: NO | R11: NO | S11: =COUNTIF(H11:R11,"YES") -> 0
B12: 8 | C12: Ramos,Delta Anne Valeen Ambre | D12: 1250275 | G12: 🟡 YELLOW | H12: NO | I12: NO | J12: NO | K12: NO | L12: NO | M12: NO | N12: NO | O12: NO | P12: NO | Q12: NO | R12: NO | S12: =COUNTIF(H12:R12,"YES") -> 0
B13: 9 | C13: Alejandrino,Ma Lourdes Fontillas | D13: 1300816 | G13: 🟡 YELLOW | H13: NO | I13: NO | J13: NO | K13: NO | L13: NO | M13: NO | N13: NO | O13: NO | P13: NO | Q13: NO | R13: NO | S13: =COUNTIF(H13:R13,"YES") -> 0
B14: 10 | C14: Guiquin,Edison Keith Calawagan | D14: 1307003 | G14: 🟡 YELLOW | H14: NO | I14: NO | J14: NO | K14: NO | L14: NO | M14: NO | N14: NO | O14: NO | P14: NO | Q14: NO | R14: NO | S14: =COUNTIF(H14:R14,"YES") -> 0

Sheet Cres Marvin Alexander Alvaro
B2: 🔍 EARLY WARNING SIGNS TRACKER — CRES MARVIN ALEXANDER ALVARO
B4: # | C4: Employee Name | D4: Employee ID | E4: Position | F4: Date Hired | G4: Risk Status | H4: Frequent Tardiness | I4: Increased Absences | J4: Low Productivity | K4: Disengagement in Team Huddles | L4: Job Hunting Signals | M4: Conflicts with Teammates | N4: Decline in QA/NPS Scores | O4: Reduced Initiative | P4: Requesting LOA/Leaves | Q4: Withdrawal from Social Activities | R4: With Active CAP? | S4: Risk Score | T4: Rating (Last 3 Mo.) | U4: TL Notes | V4: Last Updated
B5: 1 | C5: Silangan,Kathrina Mae Suycano | D5: 2254052 | G5: 🟡 YELLOW | H5: NO | I5: NO | J5: NO | K5: NO | L5: NO | M5: NO | N5: NO | O5: NO | P5: NO | Q5: NO | R5: NO | S5: =COUNTIF(H5:R5,"YES") -> 0
B6: 2 | C6: Lucresia,Sheena Estorba | D6: 2254111 | G6: 🟡 YELLOW | H6: NO | I6: NO | J6: NO | K6: NO | L6: NO | M6: NO | N6: NO | O6: NO | P6: NO | Q6: NO | R6: NO | S6: =COUNTIF(H6:R6,"YES") -> 0

Sheet Danica Villano Furiscal
B2: 🔍 EARLY WARNING SIGNS TRACKER — DANICA VILLANO FURISCAL
B4: # | C4: Employee Name | D4: Employee ID | E4: Position | F4: Date Hired | G4: Risk Status | H4: Frequent Tardiness | I4: Increased Absences | J4: Low Productivity | K4: Disengagement in Team Huddles | L4: Job Hunting Signals | M4: Conflicts with Teammates | N4: Decline in QA/NPS Scores | O4: Reduced Initiative | P4: Requesting LOA/Leaves | Q4: Withdrawal from Social Activities | R4: With Active CAP? | S4: Risk Score | T4: Rating (Last 3 Mo.) | U4: TL Notes | V4: Last Updated
B5: 1 | C5: Cacnio,Anna Katrina Salvador | D5: 1026075 | G5: 🟡 YELLOW | H5: NO | I5: NO | J5: NO | K5: NO | L5: NO | M5: NO | N5: NO | O5: NO | P5: NO | Q5: NO | R5: NO | S5: =COUNTIF(H5:R5,"YES") -> 0
B6: 2 | C6: Balboa,Maria Carmela Eugenio | D6: 1081291 | G6: 🟡 YELLOW | H6: NO | I6: NO | J6: NO | K6: NO | L6: NO | M6: NO | N6: NO | O6: NO | P6: NO | Q6: NO | R6: NO | S6: =COUNTIF(H6:R6,"YES") -> 0
B7: 3 | C7: Luzong,Erika Nica Robles | D7: 1145959 | G7: 🟡 YELLOW | H7: NO | I7: NO | J7: NO | K7: NO | L7: NO | M7: NO | N7: NO | O7: NO | P7: NO | Q7: NO | R7: NO | S7: =COUNTIF(H7:R7,"YES") -> 0
B8: 4 | C8: Baccay,Jonamie | D8: 1149651 | G8: 🟡 YELLOW | H8: NO | I8: NO | J8: NO | K8: NO | L8: NO | M8: NO | N8: NO | O8: NO | P8: NO | Q8: NO | R8: NO | S8: =COUNTIF(H8:R8,"YES") -> 0
B9: 5 | C9: Pasores,Erika Jane Rodriguez | D9: 1185804 | G9: 🟡 YELLOW | H9: NO | I9: NO | J9: NO | K9: NO | L9: NO | M9: NO | N9: NO | O9: NO | P9: NO | Q9: NO | R9: NO | S9: =COUNTIF(H9:R9,"YES") -> 0
B10: 6 | C10: Tampioc,Ma Rose Ann Casimpoy | D10: 1296850 | G10: 🟡 YELLOW | H10: NO | I10: NO | J10: NO | K10: NO | L10: NO | M10: NO | N10: NO | O10: NO | P10: NO | Q10: NO | R10: NO | S10: =COUNTIF(H10:R10,"YES") -> 0
B11: 7 | C11: Europio,Karen Remedio | D11: 1743027 | G11: 🟡 YELLOW | H11: NO | I11: NO | J11: NO | K11: NO | L11: NO | M11: NO | N11: NO | O11: NO | P11: NO | Q11: NO | R11: NO | S11: =COUNTIF(H11:R11,"YES") -> 0
